Workbook
Name LIST_FAMILY: 'Lists'!$A$2:$A$49
Name LIST_INTENSITY: 'Lists'!$C$2:$C$4
Name LIST_SILLAGE: 'Lists'!$E$2:$E$4
Name LIST_GENDER: 'Lists'!$G$2:$G$4
Name LIST_CONC: 'Lists'!$I$2:$I$3
Name LIST_YESNO: 'Lists'!$K$2:$K$3
Name LIST_NOTES: 'Lists'!$M$2:$M$152
Name LIST_SEASONKEY: 'Lists'!$N$2:$N$49
Name LIST_SEASONVAL: 'Lists'!$O$2:$O$49
Name MAP_SEASON: 'Lists'!$N$2:$O$49
Name SET_CONC: 'Settings'!$C$5
Name SET_BESTSELLER: 'Settings'!$C$7
Name SET_SHOWPRICE: 'Settings'!$C$9

Sheet Read me
B2: Siwa Fragrances — product data
B3: Three sheets to fill. Everything else is worked out from them.
B5: What to fill, in order
B6: Settings ......... 3 answers that apply to the whole catalogue. Do these first.
B7: Products ......... one row per product. The only long sheet.
B8: Heritage ......... 16 rows. Originals only — the story behind each one.
B10: Auto-calculated .. nothing to do. Shows what the three sheets above produce.
B11: Progress ......... nothing to do. Tracks how far along you are.
B12: Lists ............ the source of every dropdown. Leave it alone.
H13: Grey
B14: Cell colours | H14: Cream
B15: Grey Already known from your store. Locked. | H15: White
B16: Cream Filled in for you as a suggestion. Read it, correct it if it is wrong. | H16: Green
B17: White Yours to write.
B18: Green Calculated. Do not retype it unless you want to override it.
B20: Where the cream suggestions came from
B21: Every product on the Inspired by line references a real designer fragrance, and that
B22: fragrance's composition is public. Those pyramids were looked up on 13 Aug 2026 and
B23: filled in for you. They describe the ORIGINAL, not your version — so read each one
B24: and correct it to match what you actually blended.
B26: One check on the method: Sundaze is the only product whose own description already
B27: lists its notes. The researched pyramid for Armani Power Of You matched it exactly.
B29: The one rule that cannot bend
B30: Heritage — the oasis, the Siwan craft, the Arabic naming — belongs only to the 16
B31: products Siwa makes itself. The 40 inspired-by products stay commercial.
... B40: All of it is on the Auto-calculated sheet, with the formula visible.

Sheet Settings
B2: Catalogue-wide answers
B3: Asked once here instead of 56 times on the Products sheet.
B5: Concentration for the perfumes | D5: Your bottles say EXTRAIT DE PARFUM. Your website says Eau de Parfum. Pick the true one — it drives the product type, the spec line and Google.
B7: Reviews needed for a Best seller badge | C7: 20 | D7: A product with at least this many reviews gets the badge automatically.
B9: Show the original's retail price? | C9: No | D9: Leave as No. Naming a designer price alongside yours is a legal question, not a design one, and it has not been answered yet.
B12: Brand name published to Google | C12: Siwa Fragrances | D12: Fixed. Today Google is told the brand of 40 of your products is the designer house named in the vendor field — that is the single most damaging data problem on the store.

Sheet Products
A1: handle | B1: Product | C1: Line | D1: References | E1: The original's composition — work from this | F1: Top notes | G1: Heart notes | H1: Base notes | I1: Family 1 | J1: Family 2 | K1: Family 3 | L1: Intensity | M1: Sillage | N1: Lasts (hours) | O1: Gender | P1: Arabic name | Q1: Description (English) | R1: Description (Arabic)
A2: apple-pie | B2: Apple Pie | C2: Body care | D2: Siwa original — nothing to reference | E2: YOUR DESCRIPTION — Apple Pie A long-lasting body splash enriched with vitamin E, blending warm vanilla, delicate Apple, sweet praline, and rich cinnamon for a sensual, irresistible scent that lingers all day.
A3: chocolate-creme | B3: Chocolate Creme | C3: Originals | D3: Siwa original — nothing to reference | E3: YOUR DESCRIPTION — Chocolate Creme Gourmand fragrance for men & women. Notes: Chocolate, Vanilla, orange and woods. | O3: Unisex
A4: coffee-vanilla | B4: Coffee Vanilla | C4: Originals | D4: Siwa original — nothing to reference | E4: YOUR TEXT — Top: Coffee and Amaretto · Heart: Ice cream and Vanilla · Base: Brown Sugar and Vanilla | F4: Coffee and Amaretto | G4: Ice cream and Vanilla | H4: Brown Sugar and Vanilla
A5: gourmet | B5: Gourmet | C5: Originals | D5: Siwa original — nothing to reference | E5: YOUR DESCRIPTION — Gourmet Where Gourmand Scent meets buttery Warmth ! A warm croissant fresh from the oven, layered with sweet berries and rich blackcurrant, melts into the heart of toasted vanilla, gold butter and velvety Tonka bean base | O5: Unisex
A6: irresistible-vanilla | B6: Irresistible Vanilla | C6: Originals | D6: Siwa original — nothing to reference | E6: YOUR DESCRIPTION — Irresistible Vanilla Vanilla, sweet, powdery. Warm sweet blend of vanilla, sugar, cacao, tonka beans, red berries based on amber, musk and woods. Sexy and beautiful perfume perfect for dates and nights out. It is irresis
A7: layering-30-ml-bundle | B7: Layering bundle | C7: Bundle | D7: Siwa original — nothing to reference | E7: YOUR DESCRIPTION — Pay less get more! Enjoy a bundle of our three top layering perfumes with 15%
A8: marshmallow | B8: Marshmallow | C8: Body care | D8: Siwa original — nothing to reference | E8: YOUR DESCRIPTION — A long-lasting body splash enriched with vitamin E, sweet, warm blend of vanilla, sugar, and fluffy marshmallow.
A9: marshmallow-bundle | B9: Marshmallow Bundle | C9: Bundle | D9: Siwa original — nothing to reference | E9: YOUR DESCRIPTION — Marshmallow Bundle Enjoy additional 10% off when you buy marshmallow bundle !
A10: mawj | B10: Mawj | C10: Originals | D10: Siwa original — nothing to reference | E10: YOUR DESCRIPTION — Mawj Citrus , marine, woody Luxurios blend of sea notes, watery notes, ozonic notes, spicey notes, vanilla combined with bitter orange, pineapple, with hints of vetiver, violet, iris, jasmine with smooth touches of oud, | O10: Masculine
A11: pink-allure | B11: Pink Allure | C11: Originals | D11: Siwa original — nothing to reference | E11: YOUR TEXT — Top: Mandarin, Bergamot & soft pink pepper touch · Heart: Soft rose, peony, powdery nuances · Base: Musk, smooth woods, hint of vanilla | F11: Mandarin, Bergamot & soft pink pepper touch | G11: Soft rose, peony, powdery nuances | H11: Musk, smooth woods, hint of vanilla
A12: pink-arrogance | B12: Pink Arrogance | C12: Originals | D12: Siwa original — nothing to reference | E12: YOUR TEXT — Top: Orange blossom, neroli, almond · Heart: Jasmine, violet, apricot · Base: Musk, sandalwood | F12: Orange blossom, neroli, almond | G12: Jasmine, violet, apricot | H12: Musk, sandalwood
A13: silk-vanilla | B13: Silk Vanilla | C13: Body care | D13: Siwa original — nothing to reference | E13: YOUR DESCRIPTION — Silk Vanilla A long-lasting body splash enriched with vitamin E, blending warm vanilla, delicate orchid, sweet sugar, and rich amber for a sensual, irresistible scent that lingers all day.
A14: silk-vanilla-body-lotion | B14: Silk Vanilla Body Lotion | C14: Body care | D14: Siwa original — nothing to reference | E14: YOUR DESCRIPTION — Silk Vanilla Body Lotion Lightweight lotion enriched with Vitamin E, Panthenol, Shea Butter & Cocoa Butter. Deeply hydrates, absorbs quickly, and leaves skin silky smooth with a warm vanilla scent.
A15: sweet-rum | B15: Sweet Rum | C15: Body care | D15: Siwa original — nothing to reference | E15: YOUR DESCRIPTION — Sweet Rum A long-lasting body splash enriched with vitamin E, blending warm vanilla, delicate dates, sweet praline, and rich cinnamon for a sensual, irresistible scent that lingers all night.
A16: vanilla-91 | B16: Vanilla 91 | C16: Body care | D16: Siwa original — nothing to reference | E16: YOUR DESCRIPTION — Vanilla 91 A long-lasting body splash enriched with vitamin E, b lending creamy vanilla, soft jasmine petals and glowing sandalwood for a warm, comforting fragrance that feels sweet, cozy, and effortlessly elegant. Limit
A17: vanilla-bundle | B17: Vanilla Bundle | C17: Bundle | D17: Siwa original — nothing to reference | E17: YOUR DESCRIPTION — Vanilla Bundle – Your Everyday Glow in Luxury.. Sink into the warm, creamy essence of Silk Vanilla. This luxurious bundle features: Layering Vanilla Perfume – a rich, long-lasting scent that wraps you in sensual comfort.
A18: absolute-drunk | B18: Absolute Drunk | C18: Inspired by | D18: Sospiro — Il Padrino | E18: THE ORIGINAL — Top: Black Currant, Rum, Amaretto, Bergamot · Heart: Amber, Patchouli, Sandalwood · Base: Vanilla, Siam Benzoin, Labdanum YOUR TEXT — Top: Boozy accord with black currant · Heart: Rich patchouli, dark woods, and oriental depth · Base: Vanilla, amber warmth, and smooth woody accords | F18: Black Currant, Rum, Amaretto, Bergamot | G18: Amber, Patchouli, Sandalwood | H18: Vanilla, Siam Benzoin, Labdanum | I18: Amber | J18: Woody | K18: Sweet
A19: alluring-rose | B19: Alluring Rose | C19: Inspired by | D19: Parfums de Marly — Delina La Rosee | E19: THE ORIGINAL — Top: Lychee, Pear, Bergamot, Pink Pepper · Heart: Turkish Rose, Peony, Watery Notes, Floral Notes · Base: White Musk, Woody Notes, Vetiver YOUR DESCRIPTION — Floral fruity aquatic fragrance. Beautiful blend of rose, peony, lychee, musk, pear, vetiver with watery & floral notes. Gorgeous wearable & potent scent for daily use | F19: Lychee, Pear, Bergamot, Pink Pepper | G19: Turkish Rose, Peony, Watery Notes, Floral Notes | H19: White Musk, Woody Notes, Vetiver | I19: Floral | J19: Fruity | K19: Rose | O19: Feminine
A20: aurableu | B20: Aurableu | C20: Inspired by | D20: Louis Vuitton — Symphony | E20: THE ORIGINAL — Top: Ginger, Grapefruit, Bergamot · Heart: Fruity Notes, Aromatic Notes · Base: Woody Notes, Musk YOUR TEXT — Top: Bright citrus blend with vibrant freshness · Heart: Soft aromatic nuances and refined floral layers · Base: Clean musky undertones with subtle woody freshness and ginger | F20: Ginger, Grapefruit, Bergamot | G20: Fruity Notes, Aromatic Notes | H20: Woody Notes, Musk | I20: Citrus | J20: Fresh | K20: Aromatic
A21: bare-glow | B21: Bare Glow | C21: Inspired by | D21: Burberry — Goddess | E21: THE ORIGINAL — Top: Vanilla, Lavender, Cacao, Ginger · Heart: Vanilla Caviar · Base: Vanilla Absolute YOUR DESCRIPTION — A velvety cloud of vanilla in all its forms pure, absolute, and caviar, gently layered with calming lavender and deep cacao. Soft warmth that melts into your skin and stays close, like a gentle embrace. | F21: Vanilla, Lavender, Cacao, Ginger | G21: Vanilla Caviar | H21: Vanilla Absolute | I21: Vanilla | J21: Gourmand | K21: Sweet
A22: belle-riche | B22: Belle Riche | C22: Inspired by | D22: Jean Paul Gaultier — La Belle Le Parfum | E22: THE ORIGINAL — Top: Pear · Heart: Tonka Bean, Jasmine · Base: Vanilla YOUR DESCRIPTION — Belle Riche A seductive blend of juicy pear, rich vanilla, and creamy tonka bean, wrapped in warm jasmine and a hint of amber. A deep, addictive fragrance that captures the essence of richness & softness. | F22: Pear | G22: Tonka Bean, Jasmine | H22: Vanilla | I22: Amber | J22: Vanilla | K22: Sweet
A23: bleu-exclusive | B23: Bleu Exclusive | C23: Inspired by | D23: Chanel — Bleu de Chanel L'Exclusif | E23: THE ORIGINAL — Base: Sandalwood, Labdanum, Amber, Woody Notes ⚠ Chanel does not publish a full pyramid for this one; only the woody-amber-labdanum-sandalwood signature is stated. YOUR TEXT — Top: Soft citrus freshness with aromatic nuances · Heart: Creamy sandalwood blended with warm leathery labdanum · Base: Deep woody amber accords enriched with smooth vanilla and refined woods | F23: Soft citrus freshness with aromatic nuances | G23: Creamy sandalwood blended with warm leathery labdanum | H23: Sandalwood, Labdanum, Amber, Woody Notes | I23: Woody | J23: Aromatic | K23: Amber
A24: bleu-intense | B24: Bleu Intense | C24: Inspired by | D24: Chanel — Bleu de Chanel Parfum | E24: THE ORIGINAL — Top: Lemon Zest, Bergamot, Mint, Artemisia · Heart: Lavender, Pineapple, Geranium, Green Notes · Base: Sandalwood, Cedar, Amberwood, Iso E Super, Tonka Bean YOUR TEXT — Top: Bergamot, Lemon, Mint · Heart: Lavender, Pineapple · Base: Cedar wood, Sandalwood, Amber, Tonka Bean | F24: Lemon Zest, Bergamot, Mint, Artemisia | G24: Lavender, Pineapple, Geranium, Green Notes | H24: Sandalwood, Cedar, Amberwood, Iso E Super, Tonka Bean | I24: Woody | J24: Aromatic | K24: Citrus
A25: boujee-blush | B25: Boujee Blush | C25: Inspired by | D25: Kayali — Yum Boujee Marshmallow | 81 | E25: THE ORIGINAL — Top: Freesia, Italian Lemon, Nectarine Blossom, Apple · Heart: Marshmallow, Strawberry, Coconut, Orange Blossom · Base: Whipped Cream, Sugar, Vanilla, Musk, Raspberry, Ambroxan YOUR DESCRIPTION — Boujee Blush Yum powdery, sweet, fruity Notes: Marshmallow, strawberry, whipped cream, vanilla, coconut and musk. | F25: Freesia, Italian Lemon, Nectarine Blossom, Apple | G25: Marshmallow, Strawberry, Coconut, Orange Blossom | H25: Whipped Cream, Sugar, Vanilla, Musk, Raspberry, Ambroxan | I25: Gourmand | J25: Fruity | K25: Floral | O25: Feminine
A26: caramel-vanigliato | B26: Caramel vanigliato | C26: Inspired by | D26: Giardini di Toscana — Bianco Latte | E26: THE ORIGINAL — Top: Caramel · Heart: Coumarin, Honey · Base: Vanilla, White Musk YOUR TEXT — Top: Caramel · Heart: Coumarin and Honey · Base: Vanilla and White Musk | F26: Caramel | G26: Coumarin, Honey | H26: Vanilla, White Musk | I26: Gourmand | J26: Amber | K26: Sweet
A27: carnal-trail | B27: Carnal Trail | C27: Inspired by | D27: Initio Parfums Prives — Side Effect | E27: THE ORIGINAL — Top: Cinnamon, Rum · Heart: Tobacco, Saffron · Base: Sandalwood, Hedione YOUR DESCRIPTION — Carnal Trail Vanilla, Rum, Tobacco Irresistible boozy blend of rum, vanilla, tobacco and cinnamon. Drop dead sexy perfume gives a deep, sexy unforgettable trail. If you want to smell the sexiest person in this world Wear | F27: Cinnamon, Rum | G27: Tobacco, Saffron | H27: Sandalwood, Hedione | I27: Warm Spicy | J27: Woody | K27: Sweet
A28: citrine | B28: Citrine | C28: Inspired by | D28: Bvlgari — Le Gemme Tygar | E28: THE ORIGINAL — Top: Grapefruit · Heart: Ginger, Ambrette · Base: Ambroxan, Musk, Vetiver, Patchouli YOUR TEXT — Top: Bright and zesty grapefruit opens the scent with a burst of citrus energy, perfect for a fresh start to your day · Heart: The spice of ginger blends with soft ambrette, creating a warm, aromatic core that adds depth and character | F28: Grapefruit | G28: Ginger, Ambrette | H28: Ambroxan, Musk, Vetiver, Patchouli | I28: Citrus | J28: Aromatic | K28: Musky | O28: Masculine
A29: coco-woods | B29: Coco Woods | C29: Inspired by | D29: Matiere Premiere — Vanilla Powder | E29: THE ORIGINAL — Top: Coconut Powder, Heliotrope · Heart: Madagascar Vanilla · Base: Vanilla Absolute, White Musk, Palo Santo, Coconut, Lactones YOUR DESCRIPTION — Coco Woods Notes: Vanilla, musk, coconut powder, palo santo | F29: Coconut Powder, Heliotrope | G29: Madagascar Vanilla | H29: Vanilla Absolute, White Musk, Palo Santo, Coconut, Lactones | I29: Vanilla | J29: Powdery | K29: Coconut
A30: drunk-gold | B30: Drunk Gold | C30: Inspired by | D30: By Kilian — Angels' Share | E30: THE ORIGINAL — Top: Cognac, Cinnamon · Heart: Oak, Tonka Bean · Base: Praline, Vanilla, Sandalwood YOUR DESCRIPTION — Drunk Gold Liquid gold. Intoxication in every drop Woody, sweet, fruity Notes: Cognac, liquor, raspberry, praline, tonka | F30: Cognac, Cinnamon | G30: Oak, Tonka Bean | H30: Praline, Vanilla, Sandalwood | I30: Woody | J30: Warm Spicy | K30: Sweet
A31: hibiscusex | B31: Hibiscusex | C31: Inspired by | D31: Maison Crivelli — Hibiscus Mahajad | E31: THE ORIGINAL — Top: Spearmint, Cinnamon · Heart: Damask Rose, Hibiscus, Leather · Base: Vanilla, Ambrette YOUR DESCRIPTION — Hibiscusex Vanilla, floral, rose In a classy hotel bar, amidst the soft glow of candlelight and the whispers of conversations, a couple shared a moment of intimacy on their elegant date night. As they savored their drink | F31: Spearmint, Cinnamon | G31: Damask Rose, Hibiscus, Leather | H31: Vanilla, Ambrette | I31: Floral | J31: Sweet | K31: Rose
A32: hot-male | B32: Hot Male | C32: Inspired by | D32: Giorgio Armani — Emporio Armani Stronger With You Intensely | E32: THE ORIGINAL — Top: Pink Pepper, Juniper, Violet · Heart: Toffee, Cinnamon, Lavender, Sage · Base: Vanilla, Tonka Bean, Amber, Suede YOUR TEXT — Top: Pink Pepper, Juniper and Violet · Heart: Toffee, Cinnamon, Lavender and Sage · Base: Vanilla, Amber, Tonka Bean and Suede | F32: Pink Pepper, Juniper, Violet | G32: Toffee, Cinnamon, Lavender, Sage | H32: Vanilla, Tonka Bean, Amber, Suede | I32: Amber | J32: Sweet | K32: Gourmand | O32: Masculine
A33: hot-vanilla | B33: Hot Vanilla | C33: Inspired by | D33: Parfums de Marly — Althair | E33: THE ORIGINAL — Top: Cinnamon, Orange Blossom, Cardamom, Bergamot · Heart: Bourbon Vanilla, Elemi · Base: Praline, Musk, Ambroxan, Tonka Bean, Guaiac Wood, Candied Almond YOUR DESCRIPTION — Hot Vanilla Sweet Warm spicy Indulge your senses in the enchanting embrace of our warm perfume. A harmonious blend of cardamom and cinnamon unfolds like a comforting hug, while the richness of vanilla and praline adds a | F33: Cinnamon, Orange Blossom, Cardamom, Bergamot | G33: Bourbon Vanilla, Elemi | H33: Praline, Musk, Ambroxan, Tonka Bean, Guaiac Wood, Candied Almond | I33: Vanilla | J33: Amber | K33: Sweet
A34: insane-pineapple | B34: Insane Pineapple | C34: Inspired by | D34: Nishane — Hacivat | E34: THE ORIGINAL — Top: Pineapple, Grapefruit, Bergamot · Heart: Cedar, Patchouli, Jasmine · Base: Oakmoss, Woody Notes YOUR DESCRIPTION — Insane Pineapple Citrus, Woody, mossy Unique fresh blend of pineapple, grapefruit, bergamot, patchouli based on moss and woods. Strong summer perfume gives the feeling of sitting on the beach on a sunny day while drinkin | F34: Pineapple, Grapefruit, Bergamot | G34: Cedar, Patchouli, Jasmine | H34: Oakmoss, Woody Notes | I34: Chypre | J34: Fruity | K34: Woody | O34: Masculine
A35: iris-elixir | B35: Iris elixir | C35: Inspired by | D35: Prada — L'Homme Intense | E35: THE ORIGINAL — Top: Iris · Heart: Amber, Patchouli · Base: Tonka Bean, Leather, Sandalwood YOUR TEXT — Top: Iris · Heart: Amber and Patchouli · Base: Tonka Bean, Leather and Sandalwood | F35: Iris | G35: Amber, Patchouli | H35: Tonka Bean, Leather, Sandalwood | I35: Powdery | J35: Amber | K35: Woody | O35: Masculine
A36: lady-killer | B36: Lady killer | C36: Inspired by | D36: Parfums de Marly — Layton | E36: THE ORIGINAL — Top: Apple, Lavender, Bergamot, Mandarin Orange · Heart: Geranium, Violet, Jasmine · Base: Vanilla, Cardamom, Sandalwood, Pepper, Guaiac Wood, Patchouli, Coumarin YOUR DESCRIPTION — Lady Killer Vanilla, warm, spicy. Sexy & hot blend of vanilla green apple, cardamom, lavender, pepper, jasmine, patchouli and woods. Ideal for special occasions and dates. Its like a date night in a fancy restaurant Its | F36: Apple, Lavender, Bergamot, Mandarin Orange | G36: Geranium, Violet, Jasmine | H36: Vanilla, Cardamom, Sandalwood, Pepper, Guaiac Wood, Patchouli, Coumarin | I36: Amber | J36: Floral | K36: Vanilla | O36: Masculine
A37: lagoon-flair | B37: Lagoon Flair | C37: Inspired by | D37: Jean Paul Gaultier — Le Beau Le Parfum | E37: THE ORIGINAL — Top: Pineapple, Iris, Ginger, Cypress · Heart: Coconut, Woody Notes · Base: Tonka Bean, Sandalwood, Amber, Ambergris YOUR DESCRIPTION — Lagoon Flair Sweet, woody Notes: Coconut, Pineapple, Tonka, Woods and Iris. | F37: Pineapple, Iris, Ginger, Cypress | G37: Coconut, Woody Notes | H37: Tonka Bean, Sandalwood, Amber, Ambergris | I37: Woody | J37: Amber | K37: Coconut | O37: Masculine
A38: layering-apple | B38: Layering Apple | C38: Layering | D38: Kayali — Eden Juicy Apple | 01 | E38: THE ORIGINAL — Top: Red Apple, Blackcurrant, Pink Grapefruit, Lychee · Heart: Wild Berries, Raspberry Blossom, Jasmine, Rose Centifolia · Base: Vanilla Flower, Amber, Moss, Musk YOUR TEXT — Top: Red Apple, Litchi, Black Currant · Heart: Wild Berries, Raspberry Bloom, May Rose and Jasmine · Base: Sugar, Musk, Vanilla | F38: Red Apple, Blackcurrant, Pink Grapefruit, Lychee | G38: Wild Berries, Raspberry Blossom, Jasmine, Rose Centifolia | H38: Vanilla Flower, Amber, Moss, Musk | I38: Fruity | J38: Floral | K38: Gourmand | O38: Feminine
A39: layering-lychee | B39: Layering Lychee | C39: Layering | D39: Kayali — Eden Sparkling Lychee | 39 | E39: THE ORIGINAL — Top: Black Currant, Lychee, Italian Lemon, Red Apple · Heart: Candied Violet, Rose Damascena, Jasmine Sambac · Base: Sandalwood, Amber, Cedar, Musk, Vanilla Absolute YOUR DESCRIPTION — Layering Lychee Sweet, Fruity, vanilla Introducing our summer feminine perfume, where juicy lychee takes center stage, dancing with notes of vanilla, black currant, and a sprinkle of sugar. A delightful concoction that c | F39: Black Currant, Lychee, Italian Lemon, Red Apple | G39: Candied Violet, Rose Damascena, Jasmine Sambac | H39: Sandalwood, Amber, Cedar, Musk, Vanilla Absolute | I39: Fruity | J39: Floral | K39: Sweet | O39: Feminine
A40: layering-pistachio | B40: Layering Pistachio | C40: Layering | D40: Kayali — Yum Pistachio Gelato | 33 | E40: THE ORIGINAL — Top: Pistachio, Bergamot, Hazelnut, Rum, Cardamom · Heart: Lily-of-the-Valley, Pear, Jasmine, Peony, Geranium, White Peach, Raspberry · Base: Whipped Cream, Marshmallow, Cotton Candy, Tonka Bean, Sandalwood, Cedar, Cacao YOUR DESCRIPTION — Layering Pistachio Sweet, woody, nutty Delicious blend captivates the senses with its irresistible and edible notes including pistachio, whipped cream, roasted hazelnut, sweet rum, fluffy marshmallow, and fizzy cotton ca | F40: Pistachio, Bergamot, Hazelnut, Rum, Cardamom | G40: Lily-of-the-Valley, Pear, Jasmine, Peony, Geranium, White Peach, Raspberry | H40: Whipped Cream, Marshmallow, Cotton Candy, Tonka Bean, Sandalwood, Cedar, Cacao | I40: Gourmand | J40: Sweet | K40: Nutty
...

Sheet Heritage
A1: handle | B1: Product | C1: Where it comes from (EN) | D1: Where it comes from (AR) | E1: Ingredient origin (EN) | F1: Ingredient origin (AR) | G1: Who made it (EN) | H1: Who made it (AR) | I1: What the name means (EN) | J1: What the name means (AR)
A2: apple-pie | B2: Apple Pie
A3: chocolate-creme | B3: Chocolate Creme
A4: coffee-vanilla | B4: Coffee Vanilla
A5: gourmet | B5: Gourmet
A6: irresistible-vanilla | B6: Irresistible Vanilla
A7: layering-30-ml-bundle | B7: Layering bundle
A8: marshmallow | B8: Marshmallow
A9: marshmallow-bundle | B9: Marshmallow Bundle
A10: mawj | B10: Mawj
A11: pink-allure | B11: Pink Allure
A12: pink-arrogance | B12: Pink Arrogance
A13: silk-vanilla | B13: Silk Vanilla
... A17: vanilla-bundle | B17: Vanilla Bundle
A19: Only the 16 products Siwa makes itself are on this sheet. The 40 inspired-by products are absent by design — heritage language on a designer clone reads as decoration and the corpus rules it out.
A21: "Who made it" is for a real collaboration only. If no Siwan artisan actually worked on the product, leave it empty — an empty cell is honest, a claim is not.

Sheet Auto-calculated
A1: handle | B1: Register | C1: Concentration | D1: Product type | E1: Season | F1: Badge | G1: Launch date | H1: Card descriptors | I1: Image alt text | J1: Tags
A2: apple-pie | B2: =IF(OR(Products!C2="Inspired by",Products!C2="Layering"),"Inspired","Original") | C2: ="Body Splash" | D2: =C2 | E2: =IFERROR(VLOOKUP(Products!I2,MAP_SEASON,2,FALSE),"All season") | F2: =IF(9>=SET_BESTSELLER,"best-seller","") | G2: 2025-02-22 | H2: =TEXTJOIN(", ",TRUE,Products!I2,Products!J2,Products!K2) | I2: =TEXTJOIN(" — ",TRUE,Products!B2,Products!P2,C2)&" — Siwa Fragrances" | J2: =TEXTJOIN(", ",TRUE,"line:"&LOWER(SUBSTITUTE(Products!C2," ","-")),IF(F2="","","status:"&F2),IF(Products!O2="","","gender:"&LOWER(Products!O2)),IF(E2="","","season:"&LOWER(E2)))
A3: chocolate-creme | B3: =IF(OR(Products!C3="Inspired by",Products!C3="Layering"),"Inspired","Original") | C3: =SET_CONC | D3: =C3 | E3: =IFERROR(VLOOKUP(Products!I3,MAP_SEASON,2,FALSE),"All season") | F3: =IF(8>=SET_BESTSELLER,"best-seller","") | G3: 2024-12-06 | H3: =TEXTJOIN(", ",TRUE,Products!I3,Products!J3,Products!K3) | I3: =TEXTJOIN(" — ",TRUE,Products!B3,Products!P3,C3)&" — Siwa Fragrances" | J3: =TEXTJOIN(", ",TRUE,"line:"&LOWER(SUBSTITUTE(Products!C3," ","-")),IF(F3="","","status:"&F3),IF(Products!O3="","","gender:"&LOWER(Products!O3)),IF(E3="","","season:"&LOWER(E3)))
A4: coffee-vanilla | B4: =IF(OR(Products!C4="Inspired by",Products!C4="Layering"),"Inspired","Original") | C4: =SET_CONC | D4: =C4 | E4: =IFERROR(VLOOKUP(Products!I4,MAP_SEASON,2,FALSE),"All season") | F4: =IF(18>=SET_BESTSELLER,"best-seller","") | G4: 2024-10-21 | H4: =TEXTJOIN(", ",TRUE,Products!I4,Products!J4,Products!K4) | I4: =TEXTJOIN(" — ",TRUE,Products!B4,Products!P4,C4)&" — Siwa Fragrances" | J4: =TEXTJOIN(", ",TRUE,"line:"&LOWER(SUBSTITUTE(Products!C4," ","-")),IF(F4="","","status:"&F4),IF(Products!O4="","","gender:"&LOWER(Products!O4)),IF(E4="","","season:"&LOWER(E4)))
A5: gourmet | B5: =IF(OR(Products!C5="Inspired by",Products!C5="Layering"),"Inspired","Original") | C5: =SET_CONC | D5: =C5 | E5: =IFERROR(VLOOKUP(Products!I5,MAP_SEASON,2,FALSE),"All season") | F5: =IF(6>=SET_BESTSELLER,"best-seller","") | G5: 2025-01-09 | H5: =TEXTJOIN(", ",TRUE,Products!I5,Products!J5,Products!K5) | I5: =TEXTJOIN(" — ",TRUE,Products!B5,Products!P5,C5)&" — Siwa Fragrances" | J5: =TEXTJOIN(", ",TRUE,"line:"&LOWER(SUBSTITUTE(Products!C5," ","-")),IF(F5="","","status:"&F5),IF(Products!O5="","","gender:"&LOWER(Products!O5)),IF(E5="","","season:"&LOWER(E5)))
A6: irresistible-vanilla | B6: =IF(OR(Products!C6="Inspired by",Products!C6="Layering"),"Inspired","Original") | C6: =SET_CONC | D6: =C6 | E6: =IFERROR(VLOOKUP(Products!I6,MAP_SEASON,2,FALSE),"All season") | F6: =IF(18>=SET_BESTSELLER,"best-seller","") | G6: 2023-05-30 | H6: =TEXTJOIN(", ",TRUE,Products!I6,Products!J6,Products!K6) | I6: =TEXTJOIN(" — ",TRUE,Products!B6,Products!P6,C6)&" — Siwa Fragrances" | J6: =TEXTJOIN(", ",TRUE,"line:"&LOWER(SUBSTITUTE(Products!C6," ","-")),IF(F6="","","status:"&F6),IF(Products!O6="","","gender:"&LOWER(Products!O6)),IF(E6="","","season:"&LOWER(E6)))
A7: layering-30-ml-bundle | B7: =IF(OR(Products!C7="Inspired by",Products!C7="Layering"),"Inspired","Original") | C7: ="Bundle" | D7: =C7 | E7: =IFERROR(VLOOKUP(Products!I7,MAP_SEASON,2,FALSE),"All season") | F7: =IF(3>=SET_BESTSELLER,"best-seller","") | G7: 2024-11-14 | H7: =TEXTJOIN(", ",TRUE,Products!I7,Products!J7,Products!K7) | I7: =TEXTJOIN(" — ",TRUE,Products!B7,Products!P7,C7)&" — Siwa Fragrances" | J7: =TEXTJOIN(", ",TRUE,"line:"&LOWER(SUBSTITUTE(Products!C7," ","-")),IF(F7="","","status:"&F7),IF(Products!O7="","","gender:"&LOWER(Products!O7)),IF(E7="","","season:"&LOWER(E7)))
A8: marshmallow | B8: =IF(OR(Products!C8="Inspired by",Products!C8="Layering"),"Inspired","Original") | C8: ="Body Splash" | D8: =C8 | E8: =IFERROR(VLOOKUP(Products!I8,MAP_SEASON,2,FALSE),"All season") | F8: =IF(5>=SET_BESTSELLER,"best-seller","") | G8: 2025-05-06 | H8: =TEXTJOIN(", ",TRUE,Products!I8,Products!J8,Products!K8) | I8: =TEXTJOIN(" — ",TRUE,Products!B8,Products!P8,C8)&" — Siwa Fragrances" | J8: =TEXTJOIN(", ",TRUE,"line:"&LOWER(SUBSTITUTE(Products!C8," ","-")),IF(F8="","","status:"&F8),IF(Products!O8="","","gender:"&LOWER(Products!O8)),IF(E8="","","season:"&LOWER(E8)))
A9: marshmallow-bundle | B9: =IF(OR(Products!C9="Inspired by",Products!C9="Layering"),"Inspired","Original") | C9: ="Bundle" | D9: =C9 | E9: =IFERROR(VLOOKUP(Products!I9,MAP_SEASON,2,FALSE),"All season") | F9: =IF(4>=SET_BESTSELLER,"best-seller","") | G9: 2025-05-17 | H9: =TEXTJOIN(", ",TRUE,Products!I9,Products!J9,Products!K9) | I9: =TEXTJOIN(" — ",TRUE,Products!B9,Products!P9,C9)&" — Siwa Fragrances" | J9: =TEXTJOIN(", ",TRUE,"line:"&LOWER(SUBSTITUTE(Products!C9," ","-")),IF(F9="","","status:"&F9),IF(Products!O9="","","gender:"&LOWER(Products!O9)),IF(E9="","","season:"&LOWER(E9)))
A10: mawj | B10: =IF(OR(Products!C10="Inspired by",Products!C10="Layering"),"Inspired","Original") | C10: =SET_CONC | D10: =C10 | E10: =IFERROR(VLOOKUP(Products!I10,MAP_SEASON,2,FALSE),"All season") | F10: =IF(68>=SET_BESTSELLER,"best-seller","") | G10: 2022-06-29 | H10: =TEXTJOIN(", ",TRUE,Products!I10,Products!J10,Products!K10) | I10: =TEXTJOIN(" — ",TRUE,Products!B10,Products!P10,C10)&" — Siwa Fragrances" | J10: =TEXTJOIN(", ",TRUE,"line:"&LOWER(SUBSTITUTE(Products!C10," ","-")),IF(F10="","","status:"&F10),IF(Products!O10="","","gender:"&LOWER(Products!O10)),IF(E10="","","season:"&LOWER(E10)))
A11: pink-allure | B11: =IF(OR(Products!C11="Inspired by",Products!C11="Layering"),"Inspired","Original") | C11: =SET_CONC | D11: =C11 | E11: =IFERROR(VLOOKUP(Products!I11,MAP_SEASON,2,FALSE),"All season") | F11: =IF(14>=SET_BESTSELLER,"best-seller","") | G11: 2026-04-24 | H11: =TEXTJOIN(", ",TRUE,Products!I11,Products!J11,Products!K11) | I11: =TEXTJOIN(" — ",TRUE,Products!B11,Products!P11,C11)&" — Siwa Fragrances" | J11: =TEXTJOIN(", ",TRUE,"line:"&LOWER(SUBSTITUTE(Products!C11," ","-")),IF(F11="","","status:"&F11),IF(Products!O11="","","gender:"&LOWER(Products!O11)),IF(E11="","","season:"&LOWER(E11)))
A12: pink-arrogance | B12: =IF(OR(Products!C12="Inspired by",Products!C12="Layering"),"Inspired","Original") | C12: =SET_CONC | D12: =C12 | E12: =IFERROR(VLOOKUP(Products!I12,MAP_SEASON,2,FALSE),"All season") | F12: =IF(4>=SET_BESTSELLER,"best-seller","") | G12: 2026-04-24 | H12: =TEXTJOIN(", ",TRUE,Products!I12,Products!J12,Products!K12) | I12: =TEXTJOIN(" — ",TRUE,Products!B12,Products!P12,C12)&" — Siwa Fragrances" | J12: =TEXTJOIN(", ",TRUE,"line:"&LOWER(SUBSTITUTE(Products!C12," ","-")),IF(F12="","","status:"&F12),IF(Products!O12="","","gender:"&LOWER(Products!O12)),IF(E12="","","season:"&LOWER(E12)))
A13: silk-vanilla | B13: =IF(OR(Products!C13="Inspired by",Products!C13="Layering"),"Inspired","Original") | C13: ="Body Splash" | D13: =C13 | E13: =IFERROR(VLOOKUP(Products!I13,MAP_SEASON,2,FALSE),"All season") | F13: =IF(13>=SET_BESTSELLER,"best-seller","") | G13: 2025-02-21 | H13: =TEXTJOIN(", ",TRUE,Products!I13,Products!J13,Products!K13) | I13: =TEXTJOIN(" — ",TRUE,Products!B13,Products!P13,C13)&" — Siwa Fragrances" | J13: =TEXTJOIN(", ",TRUE,"line:"&LOWER(SUBSTITUTE(Products!C13," ","-")),IF(F13="","","status:"&F13),IF(Products!O13="","","gender:"&LOWER(Products!O13)),IF(E13="","","season:"&LOWER(E13)))
A14: silk-vanilla-body-lotion | B14: =IF(OR(Products!C14="Inspired by",Products!C14="Layering"),"Inspired","Original") | C14: ="Body Lotion" | D14: =C14 | E14: =IFERROR(VLOOKUP(Products!I14,MAP_SEASON,2,FALSE),"All season") | F14: =IF(7>=SET_BESTSELLER,"best-seller","") | G14: 2025-09-29 | H14: =TEXTJOIN(", ",TRUE,Products!I14,Products!J14,Products!K14) | I14: =TEXTJOIN(" — ",TRUE,Products!B14,Products!P14,C14)&" — Siwa Fragrances" | J14: =TEXTJOIN(", ",TRUE,"line:"&LOWER(SUBSTITUTE(Products!C14," ","-")),IF(F14="","","status:"&F14),IF(Products!O14="","","gender:"&LOWER(Products!O14)),IF(E14="","","season:"&LOWER(E14)))
A15: sweet-rum | B15: =IF(OR(Products!C15="Inspired by",Products!C15="Layering"),"Inspired","Original") | C15: ="Body Splash" | D15: =C15 | E15: =IFERROR(VLOOKUP(Products!I15,MAP_SEASON,2,FALSE),"All season") | F15: =IF(7>=SET_BESTSELLER,"best-seller","") | G15: 2025-03-02 | H15: =TEXTJOIN(", ",TRUE,Products!I15,Products!J15,Products!K15) | I15: =TEXTJOIN(" — ",TRUE,Products!B15,Products!P15,C15)&" — Siwa Fragrances" | J15: =TEXTJOIN(", ",TRUE,"line:"&LOWER(SUBSTITUTE(Products!C15," ","-")),IF(F15="","","status:"&F15),IF(Products!O15="","","gender:"&LOWER(Products!O15)),IF(E15="","","season:"&LOWER(E15)))
A16: vanilla-91 | B16: =IF(OR(Products!C16="Inspired by",Products!C16="Layering"),"Inspired","Original") | C16: ="Body Splash" | D16: =C16 | E16: =IFERROR(VLOOKUP(Products!I16,MAP_SEASON,2,FALSE),"All season") | F16: =IF(2>=SET_BESTSELLER,"best-seller","") | G16: 2026-05-16 | H16: =TEXTJOIN(", ",TRUE,Products!I16,Products!J16,Products!K16) | I16: =TEXTJOIN(" — ",TRUE,Products!B16,Products!P16,C16)&" — Siwa Fragrances" | J16: =TEXTJOIN(", ",TRUE,"line:"&LOWER(SUBSTITUTE(Products!C16," ","-")),IF(F16="","","status:"&F16),IF(Products!O16="","","gender:"&LOWER(Products!O16)),IF(E16="","","season:"&LOWER(E16)))
A17: vanilla-bundle | B17: =IF(OR(Products!C17="Inspired by",Products!C17="Layering"),"Inspired","Original") | C17: ="Bundle" | D17: =C17 | E17: =IFERROR(VLOOKUP(Products!I17,MAP_SEASON,2,FALSE),"All season") | F17: =IF(11>=SET_BESTSELLER,"best-seller","") | G17: 2025-07-17 | H17: =TEXTJOIN(", ",TRUE,Products!I17,Products!J17,Products!K17) | I17: =TEXTJOIN(" — ",TRUE,Products!B17,Products!P17,C17)&" — Siwa Fragrances" | J17: =TEXTJOIN(", ",TRUE,"line:"&LOWER(SUBSTITUTE(Products!C17," ","-")),IF(F17="","","status:"&F17),IF(Products!O17="","","gender:"&LOWER(Products!O17)),IF(E17="","","season:"&LOWER(E17)))
A18: absolute-drunk | B18: =IF(OR(Products!C18="Inspired by",Products!C18="Layering"),"Inspired","Original") | C18: =SET_CONC | D18: =C18 | E18: =IFERROR(VLOOKUP(Products!I18,MAP_SEASON,2,FALSE),"All season") | F18: =IF(2>=SET_BESTSELLER,"best-seller","") | G18: 2026-03-14 | H18: =TEXTJOIN(", ",TRUE,Products!I18,Products!J18,Products!K18) | I18: =TEXTJOIN(" — ",TRUE,Products!B18,Products!P18,C18)&" — Siwa Fragrances" | J18: =TEXTJOIN(", ",TRUE,"line:"&LOWER(SUBSTITUTE(Products!C18," ","-")),IF(F18="","","status:"&F18),IF(Products!O18="","","gender:"&LOWER(Products!O18)),IF(E18="","","season:"&LOWER(E18)))
A19: alluring-rose | B19: =IF(OR(Products!C19="Inspired by",Products!C19="Layering"),"Inspired","Original") | C19: =SET_CONC | D19: =C19 | E19: =IFERROR(VLOOKUP(Products!I19,MAP_SEASON,2,FALSE),"All season") | F19: =IF(24>=SET_BESTSELLER,"best-seller","") | G19: 2021-08-20 | H19: =TEXTJOIN(", ",TRUE,Products!I19,Products!J19,Products!K19) | I19: =TEXTJOIN(" — ",TRUE,Products!B19,Products!P19,C19)&" — Siwa Fragrances" | J19: =TEXTJOIN(", ",TRUE,"line:"&LOWER(SUBSTITUTE(Products!C19," ","-")),IF(F19="","","status:"&F19),IF(Products!O19="","","gender:"&LOWER(Products!O19)),IF(E19="","","season:"&LOWER(E19)))
A20: aurableu | B20: =IF(OR(Products!C20="Inspired by",Products!C20="Layering"),"Inspired","Original") | C20: =SET_CONC | D20: =C20 | E20: =IFERROR(VLOOKUP(Products!I20,MAP_SEASON,2,FALSE),"All season") | F20: =IF(8>=SET_BESTSELLER,"best-seller","") | G20: 2026-04-24 | H20: =TEXTJOIN(", ",TRUE,Products!I20,Products!J20,Products!K20) | I20: =TEXTJOIN(" — ",TRUE,Products!B20,Products!P20,C20)&" — Siwa Fragrances" | J20: =TEXTJOIN(", ",TRUE,"line:"&LOWER(SUBSTITUTE(Products!C20," ","-")),IF(F20="","","status:"&F20),IF(Products!O20="","","gender:"&LOWER(Products!O20)),IF(E20="","","season:"&LOWER(E20)))
A21: bare-glow | B21: =IF(OR(Products!C21="Inspired by",Products!C21="Layering"),"Inspired","Original") | C21: =SET_CONC | D21: =C21 | E21: =IFERROR(VLOOKUP(Products!I21,MAP_SEASON,2,FALSE),"All season") | F21: =IF(21>=SET_BESTSELLER,"best-seller","") | G21: 2025-11-05 | H21: =TEXTJOIN(", ",TRUE,Products!I21,Products!J21,Products!K21) | I21: =TEXTJOIN(" — ",TRUE,Products!B21,Products!P21,C21)&" — Siwa Fragrances" | J21: =TEXTJOIN(", ",TRUE,"line:"&LOWER(SUBSTITUTE(Products!C21," ","-")),IF(F21="","","status:"&F21),IF(Products!O21="","","gender:"&LOWER(Products!O21)),IF(E21="","","season:"&LOWER(E21)))
A22: belle-riche | B22: =IF(OR(Products!C22="Inspired by",Products!C22="Layering"),"Inspired","Original") | C22: =SET_CONC | D22: =C22 | E22: =IFERROR(VLOOKUP(Products!I22,MAP_SEASON,2,FALSE),"All season") | F22: =IF(4>=SET_BESTSELLER,"best-seller","") | G22: 2026-01-29 | H22: =TEXTJOIN(", ",TRUE,Products!I22,Products!J22,Products!K22) | I22: =TEXTJOIN(" — ",TRUE,Products!B22,Products!P22,C22)&" — Siwa Fragrances" | J22: =TEXTJOIN(", ",TRUE,"line:"&LOWER(SUBSTITUTE(Products!C22," ","-")),IF(F22="","","status:"&F22),IF(Products!O22="","","gender:"&LOWER(Products!O22)),IF(E22="","","season:"&LOWER(E22)))
A23: bleu-exclusive | B23: =IF(OR(Products!C23="Inspired by",Products!C23="Layering"),"Inspired","Original") | C23: =SET_CONC | D23: =C23 | E23: =IFERROR(VLOOKUP(Products!I23,MAP_SEASON,2,FALSE),"All season") | F23: =IF(19>=SET_BESTSELLER,"best-seller","") | G23: 2026-02-27 | H23: =TEXTJOIN(", ",TRUE,Products!I23,Products!J23,Products!K23) | I23: =TEXTJOIN(" — ",TRUE,Products!B23,Products!P23,C23)&" — Siwa Fragrances" | J23: =TEXTJOIN(", ",TRUE,"line:"&LOWER(SUBSTITUTE(Products!C23," ","-")),IF(F23="","","status:"&F23),IF(Products!O23="","","gender:"&LOWER(Products!O23)),IF(E23="","","season:"&LOWER(E23)))
A24: bleu-intense | B24: =IF(OR(Products!C24="Inspired by",Products!C24="Layering"),"Inspired","Original") | C24: =SET_CONC | D24: =C24 | E24: =IFERROR(VLOOKUP(Products!I24,MAP_SEASON,2,FALSE),"All season") | F24: =IF(7>=SET_BESTSELLER,"best-seller","") | G24: 2025-10-21 | H24: =TEXTJOIN(", ",TRUE,Products!I24,Products!J24,Products!K24) | I24: =TEXTJOIN(" — ",TRUE,Products!B24,Products!P24,C24)&" — Siwa Fragrances" | J24: =TEXTJOIN(", ",TRUE,"line:"&LOWER(SUBSTITUTE(Products!C24," ","-")),IF(F24="","","status:"&F24),IF(Products!O24="","","gender:"&LOWER(Products!O24)),IF(E24="","","season:"&LOWER(E24)))
A25: boujee-blush | B25: =IF(OR(Products!C25="Inspired by",Products!C25="Layering"),"Inspired","Original") | C25: =SET_CONC | D25: =C25 | E25: =IFERROR(VLOOKUP(Products!I25,MAP_SEASON,2,FALSE),"All season") | F25: =IF(59>=SET_BESTSELLER,"best-seller","") | G25: 2025-04-25 | H25: =TEXTJOIN(", ",TRUE,Products!I25,Products!J25,Products!K25) | I25: =TEXTJOIN(" — ",TRUE,Products!B25,Products!P25,C25)&" — Siwa Fragrances" | J25: =TEXTJOIN(", ",TRUE,"line:"&LOWER(SUBSTITUTE(Products!C25," ","-")),IF(F25="","","status:"&F25),IF(Products!O25="","","gender:"&LOWER(Products!O25)),IF(E25="","","season:"&LOWER(E25)))
A26: caramel-vanigliato | B26: =IF(OR(Products!C26="Inspired by",Products!C26="Layering"),"Inspired","Original") | C26: =SET_CONC | D26: =C26 | E26: =IFERROR(VLOOKUP(Products!I26,MAP_SEASON,2,FALSE),"All season") | F26: =IF(43>=SET_BESTSELLER,"best-seller","") | G26: 2024-10-08 | H26: =TEXTJOIN(", ",TRUE,Products!I26,Products!J26,Products!K26) | I26: =TEXTJOIN(" — ",TRUE,Products!B26,Products!P26,C26)&" — Siwa Fragrances" | J26: =TEXTJOIN(", ",TRUE,"line:"&LOWER(SUBSTITUTE(Products!C26," ","-")),IF(F26="","","status:"&F26),IF(Products!O26="","","gender:"&LOWER(Products!O26)),IF(E26="","","season:"&LOWER(E26)))
A27: carnal-trail | B27: =IF(OR(Products!C27="Inspired by",Products!C27="Layering"),"Inspired","Original") | C27: =SET_CONC | D27: =C27 | E27: =IFERROR(VLOOKUP(Products!I27,MAP_SEASON,2,FALSE),"All season") | F27: =IF(10>=SET_BESTSELLER,"best-seller","") | G27: 2023-09-24 | H27: =TEXTJOIN(", ",TRUE,Products!I27,Products!J27,Products!K27) | I27: =TEXTJOIN(" — ",TRUE,Products!B27,Products!P27,C27)&" — Siwa Fragrances" | J27: =TEXTJOIN(", ",TRUE,"line:"&LOWER(SUBSTITUTE(Products!C27," ","-")),IF(F27="","","status:"&F27),IF(Products!O27="","","gender:"&LOWER(Products!O27)),IF(E27="","","season:"&LOWER(E27)))
A28: citrine | B28: =IF(OR(Products!C28="Inspired by",Products!C28="Layering"),"Inspired","Original") | C28: =SET_CONC | D28: =C28 | E28: =IFERROR(VLOOKUP(Products!I28,MAP_SEASON,2,FALSE),"All season") | F28: =IF(20>=SET_BESTSELLER,"best-seller","") | G28: 2022-04-07 | H28: =TEXTJOIN(", ",TRUE,Products!I28,Products!J28,Products!K28) | I28: =TEXTJOIN(" — ",TRUE,Products!B28,Products!P28,C28)&" — Siwa Fragrances" | J28: =TEXTJOIN(", ",TRUE,"line:"&LOWER(SUBSTITUTE(Products!C28," ","-")),IF(F28="","","status:"&F28),IF(Products!O28="","","gender:"&LOWER(Products!O28)),IF(E28="","","season:"&LOWER(E28)))
A29: coco-woods | B29: =IF(OR(Products!C29="Inspired by",Products!C29="Layering"),"Inspired","Original") | C29: =SET_CONC | D29: =C29 | E29: =IFERROR(VLOOKUP(Products!I29,MAP_SEASON,2,FALSE),"All season") | F29: =IF(16>=SET_BESTSELLER,"best-seller","") | G29: 2024-07-08 | H29: =TEXTJOIN(", ",TRUE,Products!I29,Products!J29,Products!K29) | I29: =TEXTJOIN(" — ",TRUE,Products!B29,Products!P29,C29)&" — Siwa Fragrances" | J29: =TEXTJOIN(", ",TRUE,"line:"&LOWER(SUBSTITUTE(Products!C29," ","-")),IF(F29="","","status:"&F29),IF(Products!O29="","","gender:"&LOWER(Products!O29)),IF(E29="","","season:"&LOWER(E29)))
A30: drunk-gold | B30: =IF(OR(Products!C30="Inspired by",Products!C30="Layering"),"Inspired","Original") | C30: =SET_CONC | D30: =C30 | E30: =IFERROR(VLOOKUP(Products!I30,MAP_SEASON,2,FALSE),"All season") | F30: =IF(46>=SET_BESTSELLER,"best-seller","") | G30: 2025-06-24 | H30: =TEXTJOIN(", ",TRUE,Products!I30,Products!J30,Products!K30) | I30: =TEXTJOIN(" — ",TRUE,Products!B30,Products!P30,C30)&" — Siwa Fragrances" | J30: =TEXTJOIN(", ",TRUE,"line:"&LOWER(SUBSTITUTE(Products!C30," ","-")),IF(F30="","","status:"&F30),IF(Products!O30="","","gender:"&LOWER(Products!O30)),IF(E30="","","season:"&LOWER(E30)))
A31: hibiscusex | B31: =IF(OR(Products!C31="Inspired by",Products!C31="Layering"),"Inspired","Original") | C31: =SET_CONC | D31: =C31 | E31: =IFERROR(VLOOKUP(Products!I31,MAP_SEASON,2,FALSE),"All season") | F31: =IF(56>=SET_BESTSELLER,"best-seller","") | G31: 2024-05-10 | H31: =TEXTJOIN(", ",TRUE,Products!I31,Products!J31,Products!K31) | I31: =TEXTJOIN(" — ",TRUE,Products!B31,Products!P31,C31)&" — Siwa Fragrances" | J31: =TEXTJOIN(", ",TRUE,"line:"&LOWER(SUBSTITUTE(Products!C31," ","-")),IF(F31="","","status:"&F31),IF(Products!O31="","","gender:"&LOWER(Products!O31)),IF(E31="","","season:"&LOWER(E31)))
A32: hot-male | B32: =IF(OR(Products!C32="Inspired by",Products!C32="Layering"),"Inspired","Original") | C32: =SET_CONC | D32: =C32 | E32: =IFERROR(VLOOKUP(Products!I32,MAP_SEASON,2,FALSE),"All season") | F32: =IF(9>=SET_BESTSELLER,"best-seller","") | G32: 2024-06-14 | H32: =TEXTJOIN(", ",TRUE,Products!I32,Products!J32,Products!K32) | I32: =TEXTJOIN(" — ",TRUE,Products!B32,Products!P32,C32)&" — Siwa Fragrances" | J32: =TEXTJOIN(", ",TRUE,"line:"&LOWER(SUBSTITUTE(Products!C32," ","-")),IF(F32="","","status:"&F32),IF(Products!O32="","","gender:"&LOWER(Products!O32)),IF(E32="","","season:"&LOWER(E32)))
A33: hot-vanilla | B33: =IF(OR(Products!C33="Inspired by",Products!C33="Layering"),"Inspired","Original") | C33: =SET_CONC | D33: =C33 | E33: =IFERROR(VLOOKUP(Products!I33,MAP_SEASON,2,FALSE),"All season") | F33: =IF(12>=SET_BESTSELLER,"best-seller","") | G33: 2023-11-26 | H33: =TEXTJOIN(", ",TRUE,Products!I33,Products!J33,Products!K33) | I33: =TEXTJOIN(" — ",TRUE,Products!B33,Products!P33,C33)&" — Siwa Fragrances" | J33: =TEXTJOIN(", ",TRUE,"line:"&LOWER(SUBSTITUTE(Products!C33," ","-")),IF(F33="","","status:"&F33),IF(Products!O33="","","gender:"&LOWER(Products!O33)),IF(E33="","","season:"&LOWER(E33)))
A34: insane-pineapple | B34: =IF(OR(Products!C34="Inspired by",Products!C34="Layering"),"Inspired","Original") | C34: =SET_CONC | D34: =C34 | E34: =IFERROR(VLOOKUP(Products!I34,MAP_SEASON,2,FALSE),"All season") | F34: =IF(5>=SET_BESTSELLER,"best-seller","") | G34: 2023-09-21 | H34: =TEXTJOIN(", ",TRUE,Products!I34,Products!J34,Products!K34) | I34: =TEXTJOIN(" — ",TRUE,Products!B34,Products!P34,C34)&" — Siwa Fragrances" | J34: =TEXTJOIN(", ",TRUE,"line:"&LOWER(SUBSTITUTE(Products!C34," ","-")),IF(F34="","","status:"&F34),IF(Products!O34="","","gender:"&LOWER(Products!O34)),IF(E34="","","season:"&LOWER(E34)))
A35: iris-elixir | B35: =IF(OR(Products!C35="Inspired by",Products!C35="Layering"),"Inspired","Original") | C35: =SET_CONC | D35: =C35 | E35: =IFERROR(VLOOKUP(Products!I35,MAP_SEASON,2,FALSE),"All season") | F35: =IF(6>=SET_BESTSELLER,"best-seller","") | G35: 2024-06-14 | H35: =TEXTJOIN(", ",TRUE,Products!I35,Products!J35,Products!K35) | I35: =TEXTJOIN(" — ",TRUE,Products!B35,Products!P35,C35)&" — Siwa Fragrances" | J35: =TEXTJOIN(", ",TRUE,"line:"&LOWER(SUBSTITUTE(Products!C35," ","-")),IF(F35="","","status:"&F35),IF(Products!O35="","","gender:"&LOWER(Products!O35)),IF(E35="","","season:"&LOWER(E35)))
A36: lady-killer | B36: =IF(OR(Products!C36="Inspired by",Products!C36="Layering"),"Inspired","Original") | C36: =SET_CONC | D36: =C36 | E36: =IFERROR(VLOOKUP(Products!I36,MAP_SEASON,2,FALSE),"All season") | F36: =IF(26>=SET_BESTSELLER,"best-seller","") | G36: 2023-08-04 | H36: =TEXTJOIN(", ",TRUE,Products!I36,Products!J36,Products!K36) | I36: =TEXTJOIN(" — ",TRUE,Products!B36,Products!P36,C36)&" — Siwa Fragrances" | J36: =TEXTJOIN(", ",TRUE,"line:"&LOWER(SUBSTITUTE(Products!C36," ","-")),IF(F36="","","status:"&F36),IF(Products!O36="","","gender:"&LOWER(Products!O36)),IF(E36="","","season:"&LOWER(E36)))
A37: lagoon-flair | B37: =IF(OR(Products!C37="Inspired by",Products!C37="Layering"),"Inspired","Original") | C37: =SET_CONC | D37: =C37 | E37: =IFERROR(VLOOKUP(Products!I37,MAP_SEASON,2,FALSE),"All season") | F37: =IF(13>=SET_BESTSELLER,"best-seller","") | G37: 2025-04-25 | H37: =TEXTJOIN(", ",TRUE,Products!I37,Products!J37,Products!K37) | I37: =TEXTJOIN(" — ",TRUE,Products!B37,Products!P37,C37)&" — Siwa Fragrances" | J37: =TEXTJOIN(", ",TRUE,"line:"&LOWER(SUBSTITUTE(Products!C37," ","-")),IF(F37="","","status:"&F37),IF(Products!O37="","","gender:"&LOWER(Products!O37)),IF(E37="","","season:"&LOWER(E37)))
A38: layering-apple | B38: =IF(OR(Products!C38="Inspired by",Products!C38="Layering"),"Inspired","Original") | C38: =SET_CONC | D38: =C38 | E38: =IFERROR(VLOOKUP(Products!I38,MAP_SEASON,2,FALSE),"All season") | F38: =IF(1>=SET_BESTSELLER,"best-seller","") | G38: 2024-10-21 | H38: =TEXTJOIN(", ",TRUE,Products!I38,Products!J38,Products!K38) | I38: =TEXTJOIN(" — ",TRUE,Products!B38,Products!P38,C38)&" — Siwa Fragrances" | J38: =TEXTJOIN(", ",TRUE,"line:"&LOWER(SUBSTITUTE(Products!C38," ","-")),IF(F38="","","status:"&F38),IF(Products!O38="","","gender:"&LOWER(Products!O38)),IF(E38="","","season:"&LOWER(E38)))
A39: layering-lychee | B39: =IF(OR(Products!C39="Inspired by",Products!C39="Layering"),"Inspired","Original") | C39: =SET_CONC | D39: =C39 | E39: =IFERROR(VLOOKUP(Products!I39,MAP_SEASON,2,FALSE),"All season") | F39: =IF(6>=SET_BESTSELLER,"best-seller","") | G39: 2024-04-03 | H39: =TEXTJOIN(", ",TRUE,Products!I39,Products!J39,Products!K39) | I39: =TEXTJOIN(" — ",TRUE,Products!B39,Products!P39,C39)&" — Siwa Fragrances" | J39: =TEXTJOIN(", ",TRUE,"line:"&LOWER(SUBSTITUTE(Products!C39," ","-")),IF(F39="","","status:"&F39),IF(Products!O39="","","gender:"&LOWER(Products!O39)),IF(E39="","","season:"&LOWER(E39)))
A40: layering-pistachio | B40: =IF(OR(Products!C40="Inspired by",Products!C40="Layering"),"Inspired","Original") | C40: =SET_CONC | D40: =C40 | E40: =IFERROR(VLOOKUP(Products!I40,MAP_SEASON,2,FALSE),"All season") | F40: =IF(10>=SET_BESTSELLER,"best-seller","") | G40: 2023-10-27 | H40: =TEXTJOIN(", ",TRUE,Products!I40,Products!J40,Products!K40) | I40: =TEXTJOIN(" — ",TRUE,Products!B40,Products!P40,C40)&" — Siwa Fragrances" | J40: =TEXTJOIN(", ",TRUE,"line:"&LOWER(SUBSTITUTE(Products!C40," ","-")),IF(F40="","","status:"&F40),IF(Products!O40="","","gender:"&LOWER(Products!O40)),IF(E40="","","season:"&LOWER(E40)))
...

Sheet Progress
A1: Sheet | B1: Field | C1: Needed | D1: Done | E1: %
A2: Products | B2: Top notes | C2: 56 | D2: =COUNTA('Products'!F2:F57) | E2: =IF(C2=0,0,MIN(1,D2/C2))
A3: Products | B3: Heart notes | C3: 56 | D3: =COUNTA('Products'!G2:G57) | E3: =IF(C3=0,0,MIN(1,D3/C3))
A4: Products | B4: Base notes | C4: 56 | D4: =COUNTA('Products'!H2:H57) | E4: =IF(C4=0,0,MIN(1,D4/C4))
A5: Products | B5: Family 1 | C5: 56 | D5: =COUNTA('Products'!I2:I57) | E5: =IF(C5=0,0,MIN(1,D5/C5))
A6: Products | B6: Intensity | C6: 56 | D6: =COUNTA('Products'!L2:L57) | E6: =IF(C6=0,0,MIN(1,D6/C6))
A7: Products | B7: Sillage | C7: 56 | D7: =COUNTA('Products'!M2:M57) | E7: =IF(C7=0,0,MIN(1,D7/C7))
A8: Products | B8: Lasts (hours) | C8: 56 | D8: =COUNTA('Products'!N2:N57) | E8: =IF(C8=0,0,MIN(1,D8/C8))
A9: Products | B9: Gender | C9: 56 | D9: =COUNTA('Products'!O2:O57) | E9: =IF(C9=0,0,MIN(1,D9/C9))
A10: Products | B10: Arabic name (originals) | C10: 16 | D10: =COUNTA('Products'!P2:P17) | E10: =IF(C10=0,0,MIN(1,D10/C10))
A11: Products | B11: Description (English) | C11: 56 | D11: =COUNTA('Products'!Q2:Q57) | E11: =IF(C11=0,0,MIN(1,D11/C11))
A12: Products | B12: Description (Arabic) | C12: 56 | D12: =COUNTA('Products'!R2:R57) | E12: =IF(C12=0,0,MIN(1,D12/C12))
A13: Heritage | B13: Where it comes from (EN) | C13: 16 | D13: =COUNTA('Heritage'!C2:C17) | E13: =IF(C13=0,0,MIN(1,D13/C13))
A14: Heritage | B14: What the name means (EN) | C14: 16 | D14: =COUNTA('Heritage'!I2:I17) | E14: =IF(C14=0,0,MIN(1,D14/C14))
A16: The note rows start above zero because the inspired-by pyramids were researched and filled in for you. Check them before counting them as done.

Sheet Lists
A1: Scent family (Fragrantica accord) | B1: — | C1: Intensity | D1: — | E1: Sillage | F1: — | G1: Gender | H1: — | I1: Concentration | J1: — | K1: Yes / No | L1: — | M1: Fragrance notes | N1: Family | O1: → Season
A2: Amber | B2: ✔ | C2: Subtle | D2: stays close to the skin | E2: Subtle | F2: trail of about an arm's length | G2: Masculine | I2: Extrait de Parfum | J2: what the bottles are printed with | K2: Yes | M2: Akigalawood | N2: Amber | O2: Winter
A3: Animalic | C3: Distinct | D3: noticeable without dominating | E3: Distinct | F3: trail across a table | G3: Feminine | I3: Eau de Parfum | J3: what the website currently says | K3: No | M3: Amaretto | N3: Animalic | O3: Winter
A4: Anis | C4: Powerful | D4: fills the room | E4: Powerful | F4: trail across a room | G4: Unisex | M4: Amber | N4: Anis | O4: Autumn
A5: Aquatic | B5: ✔ | M5: Ambergris | N5: Aquatic | O5: Summer
A6: Aromatic | B6: ✔ | M6: Amberwood | N6: Aromatic | O6: Spring
A7: Balsamic | M7: Ambrette | N7: Balsamic | O7: Winter
A8: Cacao | M8: Ambroxan | N8: Cacao | O8: Winter
A9: Caramel | M9: Apple | N9: Caramel | O9: Winter
A10: Cherry | M10: Apricot | N10: Cherry | O10: Winter
A11: Chypre | B11: ✔ | M11: Aquatic Notes | N11: Chypre | O11: Autumn
A12: Cinnamon | M12: Aromatic Notes | N12: Cinnamon | O12: Winter
A13: Citrus | B13: ✔ | M13: Artemisia | N13: Citrus | O13: Summer
A14: Coconut | B14: ✔ | M14: Basil | N14: Coconut | O14: Summer
A15: Conifer | M15: Benzoin | N15: Conifer | O15: Autumn
A16: Earthy | M16: Bergamot | N16: Earthy | O16: Autumn
A17: Floral | B17: ✔ | M17: Bitter Orange | N17: Floral | O17: Spring
A18: Fresh | B18: ✔ | M18: Black Currant | N18: Fresh | O18: Summer
A19: Fresh Spicy | M19: Black Tea | N19: Fresh Spicy | O19: Autumn
A20: Fruity | B20: ✔ | M20: Blackcurrant | N20: Fruity | O20: Spring
A21: Gourmand | B21: ✔ | M21: Blood Orange | N21: Gourmand | O21: Winter
A22: Green | M22: Bourbon Vanilla | N22: Green | O22: Spring
A23: Herbal | M23: Brown Sugar | N23: Herbal | O23: Spring
A24: Honey | M24: Bulgarian Rose | N24: Honey | O24: Winter
A25: Iris | M25: Butter | N25: Iris | O25: Spring
A26: Lactonic | M26: Cacao | N26: Lactonic | O26: Autumn
A27: Lavender | M27: Candied Almond | N27: Lavender | O27: Spring
A28: Leather | M28: Candied Violet | N28: Leather | O28: Autumn
A29: Marine | M29: Caramel | N29: Marine | O29: Summer
A30: Mossy | M30: Cardamom | N30: Mossy | O30: Autumn
A31: Musky | B31: ✔ | M31: Carrot Seeds | N31: Musky | O31: Autumn
A32: Nutty | B32: ✔ | M32: Cashmere Wood | N32: Nutty | O32: Winter
A33: Oud | B33: ✔ | M33: Cedar | N33: Oud | O33: Winter
A34: Ozonic | M34: Cedarwood | N34: Ozonic | O34: Summer
A35: Patchouli | M35: Cinnamon | N35: Patchouli | O35: Autumn
A36: Powdery | B36: ✔ | M36: Citron | N36: Powdery | O36: Autumn
A37: Rose | B37: ✔ | M37: Clove | N37: Rose | O37: Spring
A38: Salty | B38: ✔ | M38: Coconut | N38: Salty | O38: Summer
A39: Smoky | M39: Coconut Milk | N39: Smoky | O39: Winter
A40: Soft Spicy | M40: Coconut Powder | N40: Soft Spicy | O40: Winter
...
